Workbook

Sheet Gaudi Decor
H1: ТОВ "Еліт Декор"
D3: Каталог товарів колекції "Gaudi Decor"
F4: 46272
B6: ЭД-АРТикул колекції | E6: Найменування | F6: Од. | G6: Роздрібна ціна з ПДВ, грн | H6: Примітка
A8: 1 | D8: Карниз
A9: 1 | B9: AAZG000411AA005622 | C9: AAZG000411 | D9: 1 | E9: C 1001 (2.00м) | F9: шт. | G9: 664.44
A10: 1 | B10: AAZG000411AA006875 | C10: AAZG000411 | D10: =D9+1 -> 2 | E10: C 1001 (2.00м) Flexi | F10: шт. | G10: 1328.76
A11: 1 | B11: AAZG000421AA006532 | C11: AAZG000421 | D11: =D10+1 -> 3 | E11: C 1002 (2.00м) | F11: шт. | G11: 720.48
A12: 1 | B12: AAZG000431AA006890 | C12: AAZG000431 | D12: =D11+1 -> 4 | E12: C 1003 (2.00м) | F12: шт. | G12: 546.72
A13: 1 | B13: AAZG000441AA005587 | C13: AAZG000441 | D13: =D12+1 -> 5 | E13: C 1004 (2.00м) | F13: шт. | G13: 688.56
A14: 1 | B14: AAZG000441AA006891 | C14: AAZG000441 | D14: =D13+1 -> 6 | E14: C 1004 (2.00м) Flexi | F14: шт. | G14: 1377.24
A15: 1 | B15: AAZG000471AA006897 | C15: AAZG000471 | D15: =D14+1 -> 7 | E15: C 1007 (2.00м) | F15: шт. | G15: 639.12
A16: 1 | B16: AAZG000471AA006896 | C16: AAZG000471 | D16: =D15+1 -> 8 | E16: C 1007 (2.00м) Flexi | F16: шт. | G16: 1278.24
A17: 1 | B17: AAZG000481AA005588 | C17: AAZG000481 | D17: =D16+1 -> 9 | E17: C 1008 (2.00м) | F17: шт. | G17: 522.48
A18: 1 | B18: AAZG000491AA005946 | C18: AAZG000491 | D18: =D17+1 -> 10 | E18: C 1009 (2.00м) | F18: шт. | G18: 651.24
A19: 1 | B19: AAZG000511AA006904 | C19: AAZG000511 | D19: =D18+1 -> 11 | E19: C 1010 (2.00м) | F19: шт. | G19: 653.4
A20: 1 | B20: AAZG000521AA006906 | C20: AAZG000521 | D20: =D19+1 -> 12 | E20: C 1012 (2.00м) | F20: шт. | G20: 1047.24
A21: 1 | B21: AAZG000531AA006073 | C21: AAZG000531 | D21: =D20+1 -> 13 | E21: C 1013 (2.00м) | F21: шт. | G21: 705.12
... A23: 1 | B23: AAZG000551AA005953 | C23: AAZG000551 | D23: =D22+1 -> 15 | E23: C 1015 (2.00м) | F23: шт. | G23: 886.56
B24: AAZG000501AA006902 | C24: AAZG000501 | D24: =D23+1 -> 16 | E24: C 101 (2.00м) | F24: шт. | G24: 2032.8
A25: 1 | B25: AAZG000591AA006917 | C25: AAZG000591 | D25: =D24+1 -> 17 | E25: C 102 (2.00м) | F25: шт. | G25: 2054.76
A26: 1 | B26: AAZG000651AA006892 | C26: AAZG000651 | D26: =D25+1 -> 18 | E26: C 1030 (2.00м) | F26: шт. | G26: 1027.44
A27: 1 | B27: AAZG000661AA006894 | C27: AAZG000661 | D27: =D26+1 -> 19 | E27: C 1033 (2.00м) | F27: шт. | G27: 1007.64
A28: 1 | B28: AAZG000681AA006927 | C28: AAZG000681 | D28: =D27+1 -> 20 | E28: C 1035 (2.00м) | F28: шт. | G28: 883.32
A29: 1 | B29: AAZG000701AA006900 | C29: AAZG000701 | D29: =D28+1 -> 21 | E29: C 1037 (2.00м) | F29: шт. | G29: 812.88
A30: 1 | B30: AAZG000701AA006930 | C30: AAZG000701 | D30: =D29+1 -> 22 | E30: C 1037 (2.00м) Flexi | F30: шт. | G30: 1625.76
A31: 1 | B31: AAZG000711AA006099 | C31: AAZG000711 | D31: =D30+1 -> 23 | E31: C 104 (2.00м) | F31: шт. | G31: 947.16
A32: 1 | B32: AAZG000711AA006309 | C32: AAZG000711 | D32: =D31+1 -> 24 | E32: C 104 (2.00м) Flexi | F32: шт. | G32: 1894.2
A33: 1 | B33: AAZG000721AA006199 | C33: AAZG000721 | D33: =D32+1 -> 25 | E33: C 1041 (2.00м) | F33: шт. | G33: 442.2
A34: 1 | B34: AAZG000751AA006761 | C34: AAZG000751 | D34: =D33+1 -> 26 | E34: C 1049 (2.00м) | F34: шт. | G34: 1002.12
A35: 1 | B35: AAZG000771AA000257 | C35: AAZG000771 | D35: =D34+1 -> 27 | E35: C 1061 (2.00м) | F35: шт. | G35: 1589.52
A36: 1 | B36: AAZG000781AA006693 | C36: AAZG000781 | D36: =D35+1 -> 28 | E36: C 1063 (2.00м) | F36: шт. | G36: 1013.16
... A60: 1 | B60: AAZG000991AA006311 | C60: AAZG000991 | D60: =D59+1 -> 52 | E60: C 122 (2.00м) Flexi | F60: шт. | G60: 2367.24
B61: AAZG001001AA006987 | C61: AAZG001001 | D61: =D60+1 -> 53 | E61: C 123 (2.00м) | F61: шт. | G61: 862.44
A62: 1 | B62: AAZG001001AA006986 | C62: AAZG001001 | D62: =D61+1 -> 54 | E62: C 123 (2.00м) Flexi | F62: шт. | G62: 1724.76
A63: 1 | B63: AAZG001011AA006989 | C63: AAZG001011 | D63: =D62+1 -> 55 | E63: C 124 (2.00м) | F63: шт. | G63: 938.28
A64: 1 | B64: AAZG001021AA006991 | C64: AAZG001021 | D64: =D63+1 -> 56 | E64: C 125 (2.00м) | F64: шт. | G64: 1178.16
A65: 1 | B65: AAZG001031AA006704 | C65: AAZG001031 | D65: =D64+1 -> 57 | E65: C 126 (2.00м) | F65: шт. | G65: 943.8
A66: 1 | B66: AAZG001031AA006992 | C66: AAZG001031 | D66: =D65+1 -> 58 | E66: C 126 (2.00м) Flexi | F66: шт. | G66: 1887.6
A67: 1 | B67: AAZG001041AA006994 | C67: AAZG001041 | D67: =D66+1 -> 59 | E67: C 127 (2.00м) | F67: шт. | G67: 1526.76
...

Sheet Grand Decor_NEW!!!
H1: ='Gaudi Decor'!H1 -> ТОВ "Еліт Декор"
D3: Каталог товарів колекції "Grand Decor"
F4: ='Gaudi Decor'!F4 -> 46272
A6: 1 | B6: ЭД-АРТикул колекції | D6: Найменування | F6: Од. | G6: Роздрібна ціна з ПДВ, грн | H6: Примітка
A7: 1
A8: 1 | D8: Аксесуар
A9: 1 | B9: ALZA000001AL013912 | C9: ALZA000001 | D9: 1 | E9: Світловідбиваюча стрічка, 10 м.п. | F9: шт. | G9: 36
A10: 1 | B10: ALZA000001AL013913 | C10: ALZA000001 | D10: 2 | E10: Світловідбиваюча стрічка, 20 м.п. | F10: шт. | G10: 72
A11: 1 | B11: ALZA000001AL013914 | C11: ALZA000001 | D11: 3 | E11: Світловідбиваюча стрічка, 50 м.п. | F11: шт. | G11: 180
A12: 1 | D12: Молдинг серія H
A13: 1 | B13: ALYU013871AL013134 | C13: ALYU013871 | D13: =D11+1 -> 4 | E13: HCR 501 (2.00м) | F13: шт. | G13: 179.52
A14: 1 | B14: ALYU014741AL013897 | C14: ALYU014741 | D14: =D13+1 -> 5 | E14: HCR 501 (2.00м) Flex | F14: шт. | G14: 396
A15: 1 | B15: ALYU014841AL014075 | C15: ALYU014841 | D15: =D14+1 -> 6 | E15: HCR 501-1 кутовий елемент | F15: шт. | G15: 92.4
A16: 1 | B16: ALYU015121AL014244 | C16: ALYU015121 | D16: =D15+1 -> 7 | E16: HCR 501-2 кутовий елемент | F16: шт. | G16: 132.36
A17: 1 | B17: ALYU015181AL014345 | C17: ALYU015181 | D17: =D16+1 -> 8 | E17: HCR 501-3 кутовий елемент | F17: шт. | G17: 227.88
A18: 1 | B18: ALYU013881AL013135 | C18: ALYU013881 | D18: =D17+1 -> 9 | E18: HCR 502 (2.00м) | F18: шт. | G18: 194.28
A19: 1 | B19: ALYU014501AL012951 | C19: ALYU014501 | D19: =D18+1 -> 10 | E19: HCR 502 (2.00м) Flex | F19: шт. | G19: 374.04
A20: 1 | B20: ALYU014851AL014076 | C20: ALYU014851 | D20: =D19+1 -> 11 | E20: HCR 502-1 кутовий елемент | F20: шт. | G20: 99.72
A21: 1 | B21: ALYU014961AL014174 | C21: ALYU014961 | D21: =D20+1 -> 12 | E21: HCR 502-2 кутовий елемент | F21: шт. | G21: 270.96
A22: 1 | B22: ALYU014971AL014175 | C22: ALYU014971 | D22: =D21+1 -> 13 | E22: HCR 502-3 кутовий елемент | F22: шт. | G22: 95.52
A23: 1 | B23: ALYU013891AL013136 | C23: ALYU013891 | D23: =D22+1 -> 14 | E23: HCR 503 (2.00м) | F23: шт. | G23: 194.28
A24: 1 | B24: ALYU014481AL012957 | C24: ALYU014481 | D24: =D23+1 -> 15 | E24: HCR 503 (2.00м) Flex | F24: шт. | G24: 427.92
A25: 1 | B25: ALYU013891AL015025 | C25: ALYU013891 | D25: =D24+1 -> 16 | E25: HCR 503 (3.00м) | F25: шт. | G25: 290.88
... A54: 1 | B54: ALYU015081AL014205 | C54: ALYU015081 | D54: =D53+1 -> 45 | E54: HCR 516-3 кутовий елемент | F54: шт. | G54: 135.48
B55: ALYU016491AL015986 | C55: ALYU016491 | D55: =D54+1 -> 46 | E55: HCR 516-4 кутовий елемент | F55: шт. | G55: 144.96 | H55: Новинка!!!
A56: 1 | B56: ALYU014901AL014107 | C56: ALYU014901 | D56: =D55+1 -> 47 | E56: HCR 517 (2.00м) | F56: шт. | G56: 254.16
A57: 1 | B57: ALYU015001AL014202 | C57: ALYU015001 | D57: =D56+1 -> 48 | E57: HCR 517 (2.00м) Flex | F57: шт. | G57: 512.64
A58: 1 | B58: ALYU015021AL014184 | C58: ALYU015021 | D58: =D57+1 -> 49 | E58: HCR 517-1 кутовий елемент | F58: шт. | G58: 157.56
A59: 1 | B59: ALYU015031AL014185 | C59: ALYU015031 | D59: =D58+1 -> 50 | E59: HCR 517-2 кутовий елемент | F59: шт. | G59: 219.48
A60: 1 | B60: ALYU015161AL014341 | C60: ALYU015161 | D60: =D59+1 -> 51 | E60: HCR 517-3 кутовий елемент | F60: шт. | G60: 240.48
B61: ALYU016581AL016111 | C61: ALYU016581 | D61: =D60+1 -> 52 | E61: HCR 517-4 кутовий елемент | F61: шт. | G61: 240 | H61: Новинка!!!
B62: ALYU016591AL016112 | C62: ALYU016591 | D62: =D61+1 -> 53 | E62: HCR 517/523 кутовий елемент | F62: шт. | G62: 585 | H62: Новинка!!!
A63: 1 | B63: ALYU014891AL014106 | C63: ALYU014891 | D63: =D62+1 -> 54 | E63: HCR 518 (2.00м) | F63: шт. | G63: 250.92
A64: 1 | B64: ALYU015011AL014203 | C64: ALYU015011 | D64: =D63+1 -> 55 | E64: HCR 518 (2.00м) Flex | F64: шт. | G64: 520.32
A65: 1 | B65: ALYU015041AL014186 | C65: ALYU015041 | D65: =D64+1 -> 56 | E65: HCR 518-1 кутовий елемент | F65: шт. | G65: 157.56
A66: 1 | B66: ALYU015171AL014342 | C66: ALYU015171 | D66: =D65+1 -> 57 | E66: HCR 518-2 кутовий елемент | F66: шт. | G66: 276.12
A67: 1 | B67: ALYU015191AL014346 | C67: ALYU015191 | D67: =D66+1 -> 58 | E67: HCR 518-3 кутовий елемент | F67: шт. | G67: 189
A68: 1 | B68: ALYU015581AL015189 | C68: ALYU015581 | D68: =D67+1 -> 59 | E68: HCR 519 (2.00м) | F68: шт. | G68: 330.72
A69: 1 | B69: ALYU015771AL015399 | C69: ALYU015771 | D69: =D68+1 -> 60 | E69: HCR 519 (2.00м) Flex | F69: шт. | G69: 831.6
A70: 1 | B70: ALYU015201AL014359 | C70: ALYU015201 | D70: =D69+1 -> 61 | E70: HCR 520 (2.00м) | F70: шт. | G70: 413.76
...

Sheet Harmony
H1: ='Gaudi Decor'!H1 -> ТОВ "Еліт Декор"
B3: Каталог товарів колекції "Harmony"
D4: ='Gaudi Decor'!F4 -> 46272
B6: ЭД-АРТикул колекції | D6: Найменування | F6: Од. | G6: Роздрібна ціна з ПДВ, грн | H6: Примітка
D8: Камін
B9: ABZF*****2AB001022 | D9: 1 | E9: FP 1101 | F9: шт. | G9: 27338.28
A10: 1 | D10: Карниз
A11: 1 | B11: ABZG005911AB006985 | C11: ABZG005911 | D11: =D9+1 -> 2 | E11: K 101 (2.00м) | F11: шт. | G11: 587.4
A12: 1 | B12: ABZG005941AB007003 | C12: ABZG005941 | D12: =D11+1 -> 3 | E12: K 104 (2.00м) | F12: шт. | G12: 836.04
A13: 1 | B13: ABZG005941AB007002 | C13: ABZG005941 | D13: =D12+1 -> 4 | E13: K 104 (2.00м) Flexi | F13: шт. | G13: 1671.96
A14: 1 | B14: ABZG005951AB007020 | C14: ABZG005951 | D14: =D13+1 -> 5 | E14: K 105 (2.00м) | F14: шт. | G14: 520.32
A15: 1 | B15: ABZG005951AB007013 | C15: ABZG005951 | D15: =D14+1 -> 6 | E15: K 105 (2.00м) Flexi | F15: шт. | G15: 1040.64
A16: 1 | B16: ABZG006001AB007047 | C16: ABZG006001 | D16: =D15+1 -> 7 | E16: K 1111 (2.00м) | F16: шт. | G16: 731.52
A17: 1 | B17: ABZG006001AB007045 | C17: ABZG006001 | D17: =D16+1 -> 8 | E17: K 1111 (2.00м) Flexi | F17: шт. | G17: 1463.04
A18: 1 | B18: ABZG006011AB007054 | C18: ABZG006011 | D18: =D17+1 -> 9 | E18: K 1119 (2.00м) | F18: шт. | G18: 438.96
A19: 1 | B19: ABZG006031AB007060 | C19: ABZG006031 | D19: =D18+1 -> 10 | E19: K 1122 (2.00м) | F19: шт. | G19: 805.2
A20: 1 | B20: ABZG006031AB007057 | C20: ABZG006031 | D20: =D19+1 -> 11 | E20: K 1122 (2.00м) Flexi | F20: шт. | G20: 1610.4
A21: 1 | B21: ABZG006041AB007062 | C21: ABZG006041 | D21: =D20+1 -> 12 | E21: K 1126 (2.00м) | F21: шт. | G21: 513.72
A22: 1 | B22: ABZG006061AB005945 | C22: ABZG006061 | D22: =D21+1 -> 13 | E22: K 113 (2.00м) | F22: шт. | G22: 525.84
A23: 1 | B23: ABZG006061AB007070 | C23: ABZG006061 | D23: =D22+1 -> 14 | E23: K 113 (2.00м) Flexi | F23: шт. | G23: 1051.56
... A146: 1 | B146: ABZG007381AB007301 | C146: ABZG007381 | D146: =D145+1 -> 137 | E146: K 274 (2.00м) Flexi | F146: шт. | G146: 1192.44
A147: 1 | D147: Консоль
A148: 1 | B148: ABZJ007821AB001147 | C148: ABZJ007821 | D148: =D146+1 -> 138 | E148: B 210 | F148: шт. | G148: 372.96
A149: 1 | B149: ABZJ007841AB001148 | C149: ABZJ007841 | D149: =D148+1 -> 139 | E149: B 216 | F149: шт. | G149: 795.36
A150: 1 | B150: ABZJ007851AB001855 | C150: ABZJ007851 | D150: =D149+1 -> 140 | E150: B 217 | F150: шт. | G150: 452.16
A151: 1 | B151: ABZJ007881AB001857 | C151: ABZJ007881 | D151: =D150+1 -> 141 | E151: B 222 | F151: шт. | G151: 370.68
A152: 1 | B152: ABZJ007891AB001150 | C152: ABZJ007891 | D152: =D151+1 -> 142 | E152: B 223 | F152: шт. | G152: 354.24
A153: 1 | B153: ABZJ007901AB001151 | C153: ABZJ007901 | D153: =D152+1 -> 143 | E153: B 227 | F153: шт. | G153: 928.44
A154: 1 | B154: ABZJ007911AB001152 | C154: ABZJ007911 | D154: =D153+1 -> 144 | E154: B 230 | F154: шт. | G154: 1258.44
A155: 1 | D155: Купол
A156: 1 | B156: ABZK007931AB001859 | C156: ABZK007931 | D156: =D154+1 -> 145 | E156: KR 207 | F156: шт. | G156: 6099.48
A157: 1 | D157: Молдинг
A158: 1 | B158: ABZL007941AB006115 | C158: ABZL007941 | D158: =D156+1 -> 146 | E158: M 101 (2.00м) | F158: шт. | G158: 368.52
A159: 1 | B159: ABZL007991AB007258 | C159: ABZL007991 | D159: =D158+1 -> 147 | E159: M 104 (2.00м) | F159: шт. | G159: 914.16
A160: 1 | B160: ABZL007991AB007266 | C160: ABZL007991 | D160: =D159+1 -> 148 | E160: M 104 (2.00м) Flexi | F160: шт. | G160: 1828.2
A161: 1 | B161: ABZL008021AB007260 | C161: ABZL008021 | D161: =D160+1 -> 149 | E161: M 106 (2.00м) | F161: шт. | G161: 401.52
A162: 1 | B162: ABZL008031AB001162 | C162: ABZL008031 | D162: =D161+1 -> 150 | E162: M 106-2 кутовий елемент | F162: шт. | G162: 281.64
A163: 1 | B163: ABZL008041AB007263 | C163: ABZL008041 | D163: =D162+1 -> 151 | E163: M 107 (2.00м) | F163: шт. | G163: 367.44
A164: 1 | B164: ABZL008061AB001165 | C164: ABZL008061 | D164: =D163+1 -> 152 | E164: M 107-2 кутовий елемент | F164: шт. | G164: 283.8
A165: 1 | B165: ABZL008071AB005941 | C165: ABZL008071 | D165: =D164+1 -> 153 | E165: M 108 (2.00м) | F165: шт. | G165: 518.16
...

Sheet DecoWood
H1: ='Gaudi Decor'!H1 -> ТОВ "Еліт Декор"
B3: Каталог товарів колекції "DecoWood"
D4: ='Gaudi Decor'!F4 -> 46272
B6: ЭД-АРТикул колекції | E6: Найменування | F6: Од. | G6: Роздрібна ціна з ПДВ, грн | H6: Примітка
A7: 1
A8: 1 | D8: Аксесуар
A9: 1 | B9: ACZA000001AC000002 | C9: ACZA000001 | D9: 1 | E9: Фарба для балок світла (100 мл) | F9: шт. | G9: 267 | H9: =в -> #NAME?
A10: 1 | B10: ACZA000001AC000003 | C10: ACZA000001 | D10: 2 | E10: Фарба для балок темна (100 мл) | F10: шт. | G10: 267
A11: 1 | B11: ACZA000011AC007770 | C11: ACZA000011 | D11: 3 | E11: Ремінь декоративний метал 1м | F11: шт. | G11: 325
A12: 1 | D12: Балка
A13: 1 | B13: ACZB000021AC000006 | C13: ACZB000021 | D13: =D11+1 -> 4 | E13: Модерн ED 104 (2м) classic біла 17х19 | F13: шт. | G13: 2290.2
A14: 1 | B14: ACZB000021AC000007 | C14: ACZB000021 | D14: =D13+1 -> 5 | E14: Модерн ED 104 (2м) classic світла 17х19 | F14: шт. | G14: 2290.2
A15: 1 | B15: ACZB000021AC013323 | C15: ACZB000021 | D15: =D14+1 -> 6 | E15: Модерн ED 104 (2м) classic сіра 17х19 | F15: шт. | G15: 2394.72
A16: 1 | B16: ACZB000021AC000008 | C16: ACZB000021 | D16: =D15+1 -> 7 | E16: Модерн ED 104 (2м) classic темна 17х19 | F16: шт. | G16: 2290.2
A17: 1 | B17: ACZB000021AC013255 | C17: ACZB000021 | D17: =D16+1 -> 8 | E17: Модерн ED 104 (2м) classic червона 17х19 | F17: шт. | G17: 2394.72
A18: 1 | B18: ACZB000031AC000009 | C18: ACZB000031 | D18: =D17+1 -> 9 | E18: Модерн ED 104 (3м) classic біла 17х19 | F18: шт. | G18: 3434.16
A19: 1 | B19: ACZB000031AC000010 | C19: ACZB000031 | D19: =D18+1 -> 10 | E19: Модерн ED 104 (3м) classic світла 17х19 | F19: шт. | G19: 3434.16
A20: 1 | B20: ACZB000031AC013324 | C20: ACZB000031 | D20: =D19+1 -> 11 | E20: Модерн ED 104 (3м) classic сіра 17х19 | F20: шт. | G20: 3590.4
A21: 1 | B21: ACZB000031AC000011 | C21: ACZB000031 | D21: =D20+1 -> 12 | E21: Модерн ED 104 (3м) classic темна 17х19 | F21: шт. | G21: 3434.16
A22: 1 | B22: ACZB000031AC013256 | C22: ACZB000031 | D22: =D21+1 -> 13 | E22: Модерн ED 104 (3м) classic червона 17х19 | F22: шт. | G22: 3590.4
A23: 1 | B23: ACZB000021AC000012 | C23: ACZB000021 | D23: =D22+1 -> 14 | E23: Модерн ED 104 (4м) classic біла 17х19 | F23: шт. | G23: 4575.96
A24: 1 | B24: ACZB000021AC000013 | C24: ACZB000021 | D24: =D23+1 -> 15 | E24: Модерн ED 104 (4м) classic світла 17х19 | F24: шт. | G24: 4575.96
A25: 1 | B25: ACZB000021AC013325 | C25: ACZB000021 | D25: =D24+1 -> 16 | E25: Модерн ED 104 (4м) classic сіра 17х19 | F25: шт. | G25: 4789.44
... A162: 1 | B162: ACZB000221AC013322 | C162: ACZB000221 | D162: =D161+1 -> 153 | E162: Рустик EQ 007 (4м) classic червона 6х9 | F162: шт. | G162: 2079
A163: 1 | D163: Консоль
A164: 1 | B164: ACZJ012721AC007957 | C164: ACZJ012721 | D164: =D162+1 -> 154 | E164: E 046 classic біла 14х13 | F164: шт. | G164: 412.56
A165: 1 | B165: ACZJ012721AC007958 | C165: ACZJ012721 | D165: =D164+1 -> 155 | E165: E 046 classic світла 14х13 | F165: шт. | G165: 412.56
A166: 1 | B166: ACZJ012721AC013356 | C166: ACZJ012721 | D166: =D165+1 -> 156 | E166: E 046 classic сіра 14х13 | F166: шт. | G166: 412.56
A167: 1 | B167: ACZJ012721AC007959 | C167: ACZJ012721 | D167: =D166+1 -> 157 | E167: E 046 classic темна 14х13 | F167: шт. | G167: 412.56
A168: 1 | B168: ACZJ012721AC013262 | C168: ACZJ012721 | D168: =D167+1 -> 158 | E168: E 046 classic червона 14х13 | F168: шт. | G168: 412.56
A169: 1 | B169: ACZJ000241AC000147 | C169: ACZJ000241 | D169: =D168+1 -> 159 | E169: Модерн ED 015 classic біла 19х17 | F169: шт. | G169: 495
A170: 1 | B170: ACZJ000241AC000148 | C170: ACZJ000241 | D170: =D169+1 -> 160 | E170: Модерн ED 015 classic світла 19х17 | F170: шт. | G170: 495
A171: 1 | B171: ACZJ000241AC013357 | C171: ACZJ000241 | D171: =D170+1 -> 161 | E171: Модерн ED 015 classic сіра 19х17 | F171: шт. | G171: 495
A172: 1 | B172: ACZJ000241AC000149 | C172: ACZJ000241 | D172: =D171+1 -> 162 | E172: Модерн ED 015 classic темна 19х17 | F172: шт. | G172: 495
A173: 1 | B173: ACZJ000241AC013264 | C173: ACZJ000241 | D173: =D172+1 -> 163 | E173: Модерн ED 015 classic червона 19х17 | F173: шт. | G173: 495
A174: 1 | B174: ACZJ000251AC000150 | C174: ACZJ000251 | D174: =D173+1 -> 164 | E174: Модерн ED 016 classic біла 12х12 | F174: шт. | G174: 300.36
A175: 1 | B175: ACZJ000251AC000151 | C175: ACZJ000251 | D175: =D174+1 -> 165 | E175: Модерн ED 016 classic світла 12х12 | F175: шт. | G175: 300.36
A176: 1 | B176: ACZJ000251AC013358 | C176: ACZJ000251 | D176: =D175+1 -> 166 | E176: Модерн ED 016 classic сіра 12х12 | F176: шт. | G176: 300.36
... A238: 1 | B238: ACZJ011731AC013306 | C238: ACZJ011731 | D238: =D237+1 -> 228 | E238: Рустик EQ 036 classic червона 12х12 | F238: шт. | G238: 376.2
A239: 1 | D239: Панель
...

Sheet Prestige Decor
F1: ='Gaudi Decor'!H1 -> ТОВ "Еліт Декор"
A3: Каталог товарів колекції "Prestige Decor"
B4: ='Gaudi Decor'!F4 -> 46272
A7: ЭД-АРТикул колекції | C7: Найменування | D7: Од. | E7: Роздрібна ціна з ПДВ, грн | F7: Примітка
B9: Prestige Decor
B10: Аксесуар
A11: ADZA000001AD001347 | B11: 1 | C11: Реставраційна суміш "ДарМикс" 1,5кг. | D11: шт. | E11: 429
A12: ADZA000001AD001348 | B12: =B11+1 -> 2 | C12: Реставраційна суміш "ДарМикс" 5 кг. | D12: шт. | E12: 1374.96
B13: Босаж
A14: ADZD000001AD001349 | B14: =B12+1 -> 3 | C14: BC 101 | D14: шт. | E14: 489.48
A15: ADZD000001AD001350 | B15: =B14+1 -> 4 | C15: BC 102 | D15: шт. | E15: 612.72
B16: Замок
A17: ADZE000001AD001353 | B17: =B15+1 -> 5 | C17: ZC 101 | D17: шт. | E17: 767.76
A18: ADZE000001AD001354 | B18: =B17+1 -> 6 | C18: ZC 102 | D18: шт. | E18: 873.36
A19: ADZE000001AD001355 | B19: =B18+1 -> 7 | C19: ZC 103 | D19: шт. | E19: 904.2
A20: ADZE000001AD001356 | B20: =B19+1 -> 8 | C20: ZC 104 | D20: шт. | E20: 1442.16
A21: ADZE000001AD001357 | B21: =B20+1 -> 9 | C21: ZC 105 | D21: шт. | E21: 1301.28
B22: Карниз
A23: ADZG000001AD001358 | B23: =B21+1 -> 10 | C23: KC 101 (2.00м) | D23: шт. | E23: 1098.96
A24: ADZG000001AD001359 | B24: =B23+1 -> 11 | C24: KC 102 (2.00м) | D24: шт. | E24: 1269.36
A25: ADZG000001AD001360 | B25: =B24+1 -> 12 | C25: KC 103 (2.00м) | D25: шт. | E25: 1376.16
A26: ADZG000001AD001361 | B26: =B25+1 -> 13 | C26: KC 104 (2.00м) | D26: шт. | E26: 1190.16
A27: ADZG000001AD001362 | B27: =B26+1 -> 14 | C27: KC 105 (2.00м) | D27: шт. | E27: 1488.36
A28: ADZG000001AD001363 | B28: =B27+1 -> 15 | C28: KC 106 (2.00м) | D28: шт. | E28: 1425.6
A29: ADZG000001AD001364 | B29: =B28+1 -> 16 | C29: KC 107 (2.00м) | D29: шт. | E29: 1367.28
A30: ADZG000001AD001365 | B30: =B29+1 -> 17 | C30: KC 108 (2.00м) | D30: шт. | E30: 1770.96
A31: ADZG000001AD001366 | B31: =B30+1 -> 18 | C31: KC 109 (2.00м) | D31: шт. | E31: 827.16
A32: ADZG000001AD001367 | B32: =B31+1 -> 19 | C32: KC 110 (2.00м) | D32: шт. | E32: 952.56
A33: ADZG000001AD001368 | B33: =B32+1 -> 20 | C33: KC 111 (2.00м) | D33: шт. | E33: 991.08
A34: ADZG000001AD001369 | B34: =B33+1 -> 21 | C34: KC 112 (2.00м) | D34: шт. | E34: 1068.12
A35: ADZG000001AD001370 | B35: =B34+1 -> 22 | C35: KC 113 (2.00м) | D35: шт. | E35: 1089
... A56: ADZG000001AD001391 | B56: =B55+1 -> 43 | C56: KC 134 (2.00м) | D56: шт. | E56: 3613.56
B57: Карниз універсальний
A58: ADZH000001AD001392 | B58: =B56+1 -> 44 | C58: KC 135 (2.00м) | D58: шт. | E58: 1047.24
A59: ADZH000001AD001393 | B59: =B58+1 -> 45 | C59: KC 136 (2.00м) | D59: шт. | E59: 1239.72
A60: ADZH000001AD001394 | B60: =B59+1 -> 46 | C60: KC 137 (2.00м) | D60: шт. | E60: 1329.96
A61: ADZH000001AD001395 | B61: =B60+1 -> 47 | C61: KC 138 (2.00м) | D61: шт. | E61: 1223.16
A62: ADZH000001AD001396 | B62: =B61+1 -> 48 | C62: KC 139 (2.00м) | D62: шт. | E62: 1275.96
A63: ADZH000001AD001397 | B63: =B62+1 -> 49 | C63: KC 140 (2.00м) | D63: шт. | E63: 1389.36
A64: ADZH000001AD001398 | B64: =B63+1 -> 50 | C64: KC 141 (2.00м) | D64: шт. | E64: 1459.68
...

Sheet Tesori
H1: ='Gaudi Decor'!H1 -> ТОВ "Еліт Декор"
B3: Каталог товарів колекції "TESORI"
D4: ='Gaudi Decor'!F4 -> 46272
B6: ЭД-АРТикул колекції | E6: Найменування | F6: Од. | G6: Роздрібна ціна з ПДВ, грн | H6: Примітка
A7: 1
A8: 1 | D8: Tesori
A9: 1 | D9: Аксесуар
A10: 1 | B10: AMZA000001AM005672 | E10: Реставраційна суміш "Tesori" 1,5кг. | F10: шт. | G10: 446.64
A11: 1 | D11: Карниз Серія D (Екструдований полістірол)
A12: 1 | B12: AMZG000001AM002955 | D12: 1 | E12: KD 112 (1.15м) | F12: шт. | G12: 716.16
A13: 1 | B13: AMZG000001AM002956 | D13: =D12+1 -> 2 | E13: KD 119 (1.15м) | F13: шт. | G13: 714.96
A14: 1 | B14: AMZG000001AM002957 | D14: =D13+1 -> 3 | E14: KD 201 (1.15м) | F14: шт. | G14: 507.12
A15: 1 | B15: AMZG000001AM002958 | D15: =D14+1 -> 4 | E15: KD 202 (1.15м) | F15: шт. | G15: 526.92
A16: 1 | B16: AMZG000001AM002959 | D16: =D15+1 -> 5 | E16: KD 203 (1.15м) | F16: шт. | G16: 535.68
A17: 1 | B17: AMZG000001AM002960 | D17: =D16+1 -> 6 | E17: KD 301 (1.15м) | F17: шт. | G17: 442.2
A18: 1 | B18: AMZG000001AM002961 | D18: =D17+1 -> 7 | E18: KD 302 (1.15м) | F18: шт. | G18: 467.52
A19: 1 | B19: AMZG000001AM002962 | D19: =D18+1 -> 8 | E19: KD 303 (1.15м) | F19: шт. | G19: 387.24
A20: 1 | B20: AMZG000001AM002963 | D20: =D19+1 -> 9 | E20: KD 304 (1.15м) | F20: шт. | G20: 416.88
A21: 1 | B21: AMZG000001AM002964 | D21: =D20+1 -> 10 | E21: KD 305 (1.15м) | F21: шт. | G21: 446.64
A22: 1 | B22: AMZG000001AM002965 | D22: =D21+1 -> 11 | E22: KD 306 (1.15м) | F22: шт. | G22: 521.4
A23: 1 | B23: AMZG000001AM002966 | D23: =D22+1 -> 12 | E23: KD 401 (1.15м) | F23: шт. | G23: 427.92
A24: 1 | B24: AMZG000001AM002967 | D24: =D23+1 -> 13 | E24: KD 402 (1.15м) | F24: шт. | G24: 514.8
... A29: 1 | B29: AMZG000001AM013133 | D29: =D28+1 -> 18 | E29: KD 407 (1.15м) | F29: шт. | G29: 512.64
B30: AMZG000001AM014187 | D30: =D29+1 -> 19 | E30: KD 408 (1.15м) | F30: шт. | G30: 790.92
B31: AMZG000001AM015226 | D31: =D30+1 -> 20 | E31: KD 409 (1.15м) | F31: шт. | G31: 1337.64
B32: AMZG000001AM015241 | D32: =D31+1 -> 21 | E32: KD 410 (1.15м) | F32: шт. | G32: 1087.92
B33: AMZG000001AM015319 | D33: =D32+1 -> 22 | E33: KD 411 (1.15м) | F33: шт. | G33: 1729.2
B34: AMZG000001AM015406 | D34: =D33+1 -> 23 | E34: KD 412 (1.15м) | F34: шт. | G34: 639.12
B35: AMZG000001AM015407 | D35: =D34+1 -> 24 | E35: KD 413 (1.15м) | F35: шт. | G35: 895.44
A36: 1 | B36: AMZG000001AM011841 | D36: =D35+1 -> 25 | E36: KD 502 (1.15м) | F36: шт. | G36: 467.52
A37: 1 | B37: AMZG000001AM011846 | D37: =D36+1 -> 26 | E37: KD 503 (1.15м) | F37: шт. | G37: 525.84
A38: 1 | B38: AMZG000001AM011849 | D38: =D37+1 -> 27 | E38: KD 505 (1.15м) | F38: шт. | G38: 441.12
A39: 1 | B39: AMZG000001AM011854 | D39: =D38+1 -> 28 | E39: KD 506 (1.15м) | F39: шт. | G39: 437.76
A40: 1 | D40: Карниз Серія F (поліуретан)
A41: 1 | B41: AMZG014061AM012063 | C41: =LEFT(B41,10) -> AMZG014061 | D41: =D39+1 -> 29 | E41: KF 501 ( 2.00м) | F41: шт. | G41: 569.76
A42: 1 | B42: AMZG014061AM012064 | C42: =LEFT(B42,10) -> AMZG014061 | D42: =D41+1 -> 30 | E42: KF 501 (2.00м) Flexi | F42: шт. | G42: 1138.56
A43: 1 | B43: AMZG010181AM006488 | C43: =LEFT(B43,10) -> AMZG010181 | D43: =D42+1 -> 31 | E43: KF 502 (2.00м) | F43: шт. | G43: 668.76
A44: 1 | B44: AMZG010181AM007370 | C44: =LEFT(B44,10) -> AMZG010181 | D44: =D43+1 -> 32 | E44: KF 502 (2.00м) Flexi | F44: шт. | G44: 1335.36
A45: 1 | B45: AMZG010811AM006489 | C45: =LEFT(B45,10) -> AMZG010811 | D45: =D44+1 -> 33 | E45: KF 503 (2.00м) | F45: шт. | G45: 985.56
A46: 1 | B46: AMZG010811AM007384 | C46: =LEFT(B46,10) -> AMZG010811 | D46: =D45+1 -> 34 | E46: KF 503 (2.00м) Flexi | F46: шт. | G46: 1972.32
...

Sheet Art Decor
F1: ='Gaudi Decor'!H1 -> ТОВ "Еліт Декор"
B3: Каталог товарів колекції "Art Decor"
B4: ='Gaudi Decor'!F4 -> 46272
A6: ЭД-АРТикул коллекції | C6: Найменування | D6: Од. | E6: Роздрібна ціна з ПДВ, грн | F6: Примітка
B8: Орнамент
A9: AGZQ011641AG005958 | B9: 1 | C9: A 692 | D9: шт. | E9: 327.84
A10: AGZQ011901AG006513 | B10: 2 | C10: Комплект A 693 (2шт) | D10: комплект | E10: 313.56
A11: AGZQ*****2AG006518 | B11: 3 | C11: Комплект A 694 L/R (2шт) | D11: комплект | E11: 387.24
A12: AGZQ011921AG006514 | B12: 4 | C12: Комплект A 695 (2шт) | D12: комплект | E12: 273.96
A13: AGZQ*****2AG006668 | B13: 5 | C13: Комплект A 695 (4шт) A 698 (1шт) | D13: комплект | E13: 674.28
A14: AGZQ*****2AG006519 | B14: 6 | C14: Комплект A 696 L/R (4шт) | D14: комплект | E14: 549.96
A15: AGZQ011941AG006515 | B15: 7 | C15: Комплект A 697 (2шт) | D15: комплект | E15: 279.36
A16: AGZQ*****2AG006669 | B16: 8 | C16: Комплект A 697 (4шт) A699 (1шт) | D16: комплект | E16: 687.48
A17: AGZQ011951AG006516 | B17: 9 | C17: Комплект A 698 (2шт) | D17: комплект | E17: 256.32
A18: AGZQ011961AG006517 | B18: 10 | C18: Комплект A 699 (2шт) | D18: комплект | E18: 259.56
A19: AGZQ*****2AG006520 | B19: 11 | C19: Комплект A 700 L/R (2шт) | D19: комплект | E19: 431.16
A20: AGZQ*****2AG006521 | B20: 12 | C20: Комплект A 701 L/R (2шт) | D20: комплект | E20: 392.76
B21: Панель декоративна
A22: AGYP014621AG013615 | B22: =B20+1 -> 13 | C22: W 365 Квадрати (487х487х20 мм) | D22: шт. | E22: 897.6
A23: AGYP014651AG013637 | B23: =B22+1 -> 14 | C23: W 367 Квадрат (97х97х20 мм) (вставка да панелі W 365) | D23: шт. | E23: 83.64
A24: AGYP015511AG015160 | B24: =B23+1 -> 15 | C24: W 370 (2000х250х16 мм) | D24: шт. | E24: 1897.56
A25: AGYP015511AG015161 | B25: =B24+1 -> 16 | C25: W 370 Flex (2000х250х10 мм) | D25: шт. | E25: 3795
A26: AGYP015461AG015147 | B26: =B25+1 -> 17 | C26: W 370 (2800х250х16 мм) | D26: шт. | E26: 2656.56
A27: AGYP015461AG015159 | B27: =B26+1 -> 18 | C27: W 370 Flex (2800х250х10 мм) | D27: шт. | E27: 5313
A28: AGYP015531AG015164 | B28: =B27+1 -> 19 | C28: W 371 (2000х250х19 мм) | D28: шт. | E28: 2216.04
A29: AGYP015521AG015162 | B29: =B28+1 -> 20 | C29: W 371 (2800х250х19 мм) | D29: шт. | E29: 3098.04
A30: AGYP015621AG015229 | B30: =B29+1 -> 21 | C30: W 372 (2800х250х16 мм) | D30: шт. | E30: 2483.76
A31: AGYP015621AG015230 | B31: =B30+1 -> 22 | C31: W 372 Flex (2800х250х16 мм) | D31: шт. | E31: 4966.56
A32: AGYP015761AG015393 | B32: =B31+1 -> 23 | C32: W 374 (2800х215х19 мм) | D32: шт. | E32: 2420.04
A33: AGYP015901AG015538 | B33: =B32+1 -> 24 | C33: W 376 (2800х250х12,5 мм) | D33: шт. | E33: 2656.56
A34: AGYP015901AG015541 | B34: =B33+1 -> 25 | C34: W 376 Flex (2800х250х12,5 мм) | D34: шт. | E34: 5313
... A46: ALXE016321AL015787 | B46: =B45+1 -> 37 | C46: HW 375 (2.80м) (полімер HDPS) | D46: шт. | E46: 1984.56
B47: Символи
A48: AGYQ005881AG003457 | B48: =B46+1 -> 38 | C48: 0 | D48: шт. | E48: 226.56
A49: AGYQ005891AG003459 | B49: =B48+1 -> 39 | C49: 1 | D49: шт. | E49: 226.56
A50: AGYQ013681AG003460 | B50: =B49+1 -> 40 | C50: 2 | D50: шт. | E50: 226.56
A51: AGYQ013691AG003461 | B51: =B50+1 -> 41 | C51: 3 | D51: шт. | E51: 226.56
A52: AGYQ013701AG003469 | B52: =B51+1 -> 42 | C52: 4 | D52: шт. | E52: 226.56
A53: AGYQ013711AG003470 | B53: =B52+1 -> 43 | C53: 5 | D53: шт. | E53: 226.56
A54: AGYQ013721AG003472 | B54: =B53+1 -> 44 | C54: 6 | D54: шт. | E54: 226.56
...

Sheet Arxat
F1: ='Gaudi Decor'!H1 -> ТОВ "Еліт Декор"
B3: Каталог товарів колекції "Arxat"
B4: ='Gaudi Decor'!F4 -> 46272
A6: ЭД-АРТикул коллекції | B6: Найменування | C6: Од. | D6: Од. | E6: Роздрібна ціна з ПДВ, грн | F6: Примітка
B8: Орнамент
A9: AZZQ012091AZ006645 | B9: 1 | C9: Комплект A 702 (30шт) | D9: комплект | E9: 432.36
A10: AZZQ012101AZ006646 | B10: 2 | C10: Комплект A 703 (12шт) | D10: комплект | E10: 864.6
A11: AZZQ012111AZ006647 | B11: 3 | C11: Комплект A 704 (4шт) | D11: комплект | E11: 171.6
A12: AZZQ012121AZ006648 | B12: 4 | C12: Комплект A 705 (8шт) | D12: комплект | E12: 1112.16
A13: AZZQ012131AZ006649 | B13: 5 | C13: Комплект A 706 (4шт) | D13: комплект | E13: 521.4
A14: AZZQ012141AZ006651 | B14: 6 | C14: Комплект A 707 (2шт) | D14: комплект | E14: 470.76
A15: AZZQ012161AZ006717 | B15: 7 | C15: Комплект A 708 (4шт) | D15: комплект | E15: 536.76
A16: AZZQ*****2AZ006664 | B16: 8 | C16: Комплект A 708/A706 (4шт) | D16: комплект | E16: 1056
A17: AZZQ012151AZ006652 | B17: 9 | C17: Комплект A 709 (2шт) | D17: комплект | E17: 521.4
A18: AZZQ*****2AZ006665 | B18: 10 | C18: Комплект A 709/A707 (2шт) | D18: комплект | E18: 987.84
A19: AZZQ012171AZ006659 | B19: 11 | C19: Комплект A 710 (4шт) | D19: комплект | E19: 712.8
A20: AZZQ012181AZ006660 | B20: 12 | C20: Комплект A 711 (2шт) | D20: комплект | E20: 662.16
... A27: AZZQ012231AZ006150 | B27: 19 | C27: A 716 | D27: шт. | E27: 474.12

Sheet Рекламна Продукція
F1: ='Gaudi Decor'!H1 -> ТОВ "Еліт Декор"
B3: Рекламна продукція
C4: ='Gaudi Decor'!F4 -> 46272
A6: ЭД-АРТикул коллекції | C6: Найменування | D6: Од. | E6: Роздрібна ціна з ПДВ, грн | F6: Примітка
B8: Демонстраційний бокс
A9: AXYL000001AX007448 | B9: 1 | C9: Art | D9: шт. | E9: 350
A10: AXYL000001AX007452 | B10: =B9+1 -> 2 | C10: Arxat | D10: шт. | E10: 700
A11: AXYL000001AX005966 | B11: =B10+1 -> 3 | C11: Deco Wood №1 16S | D11: шт. | E11: 460
A12: AXYL000001AX005967 | B12: =B11+1 -> 4 | C12: Gaudi Decor №1 16S | D12: шт. | E12: 900
A13: AXYL000001AX005970 | B13: =B12+1 -> 5 | C13: Harmony №1 16S | D13: шт. | E13: 900
A14: AXYL000001AX003528 | B14: =B13+1 -> 6 | C14: Prestige Decor LED 16S | D14: шт. | E14: 418
A15: AXYL000001AX005706 | B15: =B14+1 -> 7 | C15: Prestige Decor №1 16S | D15: шт. | E15: 418
A16: AXYL000001AX006279 | B16: =B15+1 -> 8 | C16: Набір нарізок Gaudi Decor 30 см | D16: шт. | E16: 1400
A17: AXYL000001AX006282 | B17: =B16+1 -> 9 | C17: Набір нарізок Harmony 30 см | D17: шт. | E17: 1400
A18: AXYL000001AX005707 | B18: =B17+1 -> 10 | C18: Набір нарізок Tesori серия D 16 см | D18: шт. | E18: 418
A19: AXYL000001AX006288 | B19: =B18+1 -> 11 | C19: Набір нарізок Tesori серия D 30 см | D19: шт. | E19: 900
A20: AXYL000001AX006322 | B20: =B19+1 -> 12 | C20: Набір нарізок Tesori серия F 16 см | D20: шт. | E20: 900
A21: AXYL000001AX006291 | B21: =B20+1 -> 13 | C21: Набір нарізок Tesori серия F 30 см | D21: шт. | E21: 1400
... A25: AXYL000001AX012632 | B25: =B24+1 -> 17 | C25: Набір Символів для стенда | D25: шт. | E25: 5560
B26: Каталог
A27: AXZZ000001AX005973 | B27: =B25+1 -> 18 | C27: Deco Wood А5 | D27: шт. | E27: 10
A28: AXZZ000001AX005977 | B28: =B27+1 -> 19 | C28: Prestige Decor А5 | D28: шт. | E28: 35
A29: AXZZ000001AX005978 | B29: =B28+1 -> 20 | C29: Tesori серія D А5 | D29: шт. | E29: 20
A30: AXZZ000001AX008111 | B30: =B29+1 -> 21 | C30: Tesori серія F A5 | D30: шт. | E30: 20
A31: AXZZ000001AX007419 | B31: =B30+1 -> 22 | C31: Arxat/Art А5 | D31: шт. | E31: 14
B32: Стенд
A33: AXZZ000001AX010536 | B33: =B31+1 -> 23 | C33: Стенд книжка Tesori F | D33: шт. | E33: 678
A34: AXZZ000001AX003357 | B34: =B33+1 -> 24 | C34: Стенд Модуль "Art Decor" | D34: шт. | E34: 1500
A35: AXZZ000001AX003358 | B35: =B34+1 -> 25 | C35: Стенд Модуль "Art Літери" | D35: шт. | E35: 1500
A36: AXZZ000001AX003359 | B36: =B35+1 -> 26 | C36: Стенд Модуль "Arxat" | D36: шт. | E36: 1500
A37: AXZZ000001AX003374 | B37: =B36+1 -> 27 | C37: Стенд Модуль "DecoWood" | D37: шт. | E37: 1500
A38: AXZZ000001AX003380 | B38: =B37+1 -> 28 | C38: Стенд Модуль "Gaudi Decor, Harmony" | D38: шт. | E38: 1500
A39: AXZZ000001AX003376 | B39: =B38+1 -> 29 | C39: Стенд Модуль "Prestige Decor Led" | D39: шт. | E39: 2000
A40: AXZZ000001AX003377 | B40: =B39+1 -> 30 | C40: Стенд Модуль "Prestige Decor" | D40: шт. | E40: 1500
A41: AXZZ000001AX009172 | B41: =B40+1 -> 31 | C41: Стенд Модуль "Tesori D" | D41: шт. | E41: 2000
A42: AXZZ000001AX003363 | B42: =B41+1 -> 32 | C42: Стенд Модуль "Tesori F" | D42: шт. | E42: 2000
A43: AXZZ000001AX012295 | B43: =B42+1 -> 33 | C43: Стенд стойка "Буквы" на 40 ячеек | D43: шт. | E43: 1200
A44: AXZZ000001AX003378 | B44: =B43+1 -> 34 | C44: Основа трикутник | D44: шт. | E44: 145
A45: AXZZ000001AX003379 | B45: =B44+1 -> 35 | C45: Основа чотирикутник | D45: шт. | E45: 232
